Workbook

Sheet R016-01
E1: REGISTRO DE INSPECCION DE PRODUCTO - ROD. DE BOLAS | V1: REGISTRO DE INSPECCION DE PRODUCTO - ROD. DE BOLAS
E3: RADIAL BALL BEARING INSPECTION RECORD | V3: RADIAL BALL BEARING INSPECTION RECORD
E5: R016 - 01 | I5: 42895 | K5: REV. | L5: 10 | M5: PAG. 01 - 01 | V5: R016 - 01 | Z5: 42895 | AB5: REV. | AC5: 10 | AD5: PAG. 01 - 01
A7: UBIC. EN DEPOSITO LOCATION IN DEPOSITS: | I7: PRODUCTO / PRODUCT: | R7: UBIC. EN DEPOSITO LOCATION IN DEPOSITS: | Z7: PRODUCTO / PRODUCT:
A8: PROVEEDOR SUPPLIER: | I8: =VLOOKUP(Auxiliar!B1,Auxiliar!A3:AI647,29,FALSE) | L8: REV. PRINT | N8: =VLOOKUP(Auxiliar!B1,Auxiliar!A3:AI647,30,FALSE) | R8: PROVEEDOR SUPPLIER: | Z8: =VLOOKUP(Auxiliar!B1,Auxiliar!A3:AI647,29,FALSE) | AC8: REV. PRINT | AE8: =VLOOKUP(Auxiliar!B1,Auxiliar!A3:AI647,30,FALSE)
A9: LUGAR DE INSPEC. NAME OF INSPECTION FACILITY: | D9: LABORATORIO BPB | I9: CRITERIO DE MUESTRA / SAMPLE DISCRETION: | N9: Prod.Armado Partes | R9: LUGAR DE INSPEC. NAME OF INSPECTION FACILITY: | U9: LABORATORIO BPB | Z9: CRITERIO DE MUESTRA / SAMPLE DISCRETION: | AE9: Prod.Armado Partes
A10: DOC. DE REF. (PO#/PI#): | I10: PARTIDA/ BATCH: | R10: DOC. DE REF. (PO#/PI#): | Z10: PARTIDA/ BATCH:
A11: ITEM | B11: D.Nominal NOMINAL DIM. (mm) | C11: Instrumento / Instrument (Codigo) | D11: Tolerancia Tolerance (µm) | E11: MEDICIONES /ACTUAL READINGS (µm) | O11: RESULTADO/ RESULT | R11: ITEM | S11: D.Nominal NOMINAL DIM. (mm) | T11: Instrumento / Instrument (Codigo) | U11: Tolerancia Tolerance (µm) | V11: MEDICIONES /ACTUAL READINGS (µm) | AF11: RESULTADO/ RESULT
E13: Nº 1 | F13: Nº 2 | G13: Nº 3 | H13: Nº 4 | I13: Nº 5 | J13: Nº 6 | K13: Nº 7 | L13: Nº 8 | M13: Nº 9 | N13: Nº 10 | V13: Nº 1 | W13: Nº 2 | X13: Nº 3 | Y13: Nº 4 | Z13: Nº 5 | AA13: Nº 6 | AB13: Nº 7 | AC13: Nº 8 | AD13: Nº 9 | AE13: Nº 10
A14: C | B14: =VLOOKUP(Auxiliar!B1,Auxiliar!A3:AI4998,3,FALSE) | D14: =VLOOKUP(Auxiliar!B1,Auxiliar!A3:AI4998,4,FALSE) | R14: C | S14: =VLOOKUP(Auxiliar!B1,Auxiliar!A3:AI4998,3,FALSE) | U14: 0
D15: =VLOOKUP(Auxiliar!B1,Auxiliar!A3:AI4998,5,FALSE) | U15: -120
A16: D | B16: =VLOOKUP(Auxiliar!B1,Auxiliar!A3:AI4998,6,FALSE) | D16: =VLOOKUP(Auxiliar!B1,Auxiliar!A3:AI4998,7,FALSE) | R16: D | S16: =VLOOKUP(Auxiliar!B1,Auxiliar!A3:AI4998,6,FALSE) | U16: =VLOOKUP(Auxiliar!B1,Auxiliar!A3:AI4998,7,FALSE)
D17: =VLOOKUP(Auxiliar!B1,Auxiliar!A3:AI6488,8,FALSE) | U17: =VLOOKUP(Auxiliar!B1,Auxiliar!A3:AI6488,8,FALSE)
A18: B | B18: =VLOOKUP(Auxiliar!B1,Auxiliar!A3:AI4998,9,FALSE) | D18: =VLOOKUP(Auxiliar!B1,Auxiliar!A3:AI6488,10,FALSE) | R18: B | S18: =VLOOKUP(Auxiliar!B1,Auxiliar!A3:AI4998,9,FALSE) | U18: =VLOOKUP(Auxiliar!B1,Auxiliar!A3:AI6488,10,FALSE)
D19: =VLOOKUP(Auxiliar!B1,Auxiliar!A3:AI6488,11,FALSE) | U19: =VLOOKUP(Auxiliar!B1,Auxiliar!A3:AI6488,11,FALSE)
A20: d | B20: =VLOOKUP(Auxiliar!B1,Auxiliar!A3:AI4998,12,FALSE) | D20: =VLOOKUP(Auxiliar!B1,Auxiliar!A3:AI6488,13,FALSE) | R20: d | S20: =VLOOKUP(Auxiliar!B1,Auxiliar!A3:AI4998,12,FALSE) | U20: =VLOOKUP(Auxiliar!B1,Auxiliar!A3:AI6488,13,FALSE)
D21: =VLOOKUP(Auxiliar!B1,Auxiliar!A3:AI6488,14,FALSE) | U21: =VLOOKUP(Auxiliar!B1,Auxiliar!A3:AI6488,14,FALSE)
A22: GA | B22: =VLOOKUP(Auxiliar!B1,Auxiliar!A3:AI4998,18,FALSE) | D22: =VLOOKUP(Auxiliar!B1,Auxiliar!A3:AI6488,19,FALSE) | R22: GA | S22: =VLOOKUP(Auxiliar!B1,Auxiliar!A3:AI4998,18,FALSE) | U22: =VLOOKUP(Auxiliar!B1,Auxiliar!A3:AI6488,19,FALSE)
D23: =VLOOKUP(Auxiliar!B1,Auxiliar!A3:AI6488,20,FALSE) | U23: =VLOOKUP(Auxiliar!B1,Auxiliar!A3:AI6488,20,FALSE)
A24: GR | B24: =VLOOKUP(Auxiliar!B1,Auxiliar!A3:AI4998,15,FALSE) | D24: =VLOOKUP(Auxiliar!B1,Auxiliar!A3:AI6488,16,FALSE) | R24: GR | S24: =VLOOKUP(Auxiliar!B1,Auxiliar!A3:AI4998,15,FALSE) | U24: =VLOOKUP(Auxiliar!B1,Auxiliar!A3:AI6488,16,FALSE)
D25: =VLOOKUP(Auxiliar!B1,Auxiliar!A3:AI6488,17,FALSE) | U25: =VLOOKUP(Auxiliar!B1,Auxiliar!A3:AI6488,17,FALSE)
A26: RUIDO / NOISE | R26: RUIDO / NOISE
A27: DUREZA Hardness (HRC) | B27: ARO INTERIOR / INNER RING | D27: =VLOOKUP(Auxiliar!B1,Auxiliar!A3:AI6488,21,FALSE) | R27: DUREZA Hardness (HRC) | S27: ARO INTERIOR / INNER RING | U27: =VLOOKUP(Auxiliar!B1,Auxiliar!A3:AI6488,21,FALSE)
D28: =VLOOKUP(Auxiliar!B1,Auxiliar!A3:AI6488,22,FALSE) | U28: =VLOOKUP(Auxiliar!B1,Auxiliar!A3:AI6488,22,FALSE)
B29: ARO EXTERIOR / OUTER RING | D29: =VLOOKUP(Auxiliar!B1,Auxiliar!A3:AI6488,23,FALSE) | S29: ARO EXTERIOR / OUTER RING | U29: =VLOOKUP(Auxiliar!B1,Auxiliar!A3:AI6488,23,FALSE)
D30: =VLOOKUP(Auxiliar!B1,Auxiliar!A3:AI6488,24,FALSE) | U30: =VLOOKUP(Auxiliar!B1,Auxiliar!A3:AI6488,24,FALSE)
A31: Ra | B31: PISTA I.R./ I.R. RACEWAY | R31: Ra | S31: PISTA I.R./ I.R. RACEWAY
B32: PISTA O.R. / O.R. RACEWAY | S32: PISTA O.R. / O.R. RACEWAY
B33: BOLITA / BALL | S33: BOLITA / BALL
A34: ESTADO DE LOS SELLOS / SEAL APPEARANCE | R34: ESTADO DE LOS SELLOS / SEAL APPEARANCE
A35: ANCLAJE DE SELLOS/ SEAL STACKING TEST | R35: ANCLAJE DE SELLOS/ SEAL STACKING TEST
A36: TORQUE DE SELLLOS / SEAL RUNNIG TORQUE | D36: =VLOOKUP(Auxiliar!B1,Auxiliar!A3:AI6488,27,FALSE) | R36: TORQUE DE SELLLOS / SEAL RUNNIG TORQUE | U36: =VLOOKUP(Auxiliar!B1,Auxiliar!A3:AI6488,27,FALSE)
D37: =VLOOKUP(Auxiliar!B1,Auxiliar!A3:AI6488,28,FALSE) | U37: =VLOOKUP(Auxiliar!B1,Auxiliar!A3:AI6488,28,FALSE)
A38: GRABADO / MARKING | R38: GRABADO / MARKING
A39: ASPECTO | C39: * Rayas, Golpes, Oxido, Desprendimiento de material | R39: ASPECTO | T39: * Rayas, Golpes, Oxido, Desprendimiento de material
A40: Peso Rodamiento / Assembled Bearing Weight | R40: Peso Rodamiento / Assembled Bearing Weight
A41: Peso Rodamiento sin Grasa / Washed Assembled Bearing Weight | R41: Peso Rodamiento sin Grasa / Washed Assembled Bearing Weight
A42: Peso de Grasa (grs) / Grease Weight (grs) | D42: =VLOOKUP(Auxiliar!B1,Auxiliar!A15:AI6488,25,FALSE) | R42: Peso de Grasa (grs) / Grease Weight (grs) | U42: =VLOOKUP(Auxiliar!B1,Auxiliar!A15:AI6488,25,FALSE)
A43: Tipo de grasa/ grease type | D43: =VLOOKUP(Auxiliar!B1,Auxiliar!A15:AI6488,26,FALSE) | R43: Tipo de grasa/ grease type | U43: =VLOOKUP(Auxiliar!B1,Auxiliar!A15:AI6488,26,FALSE)
A44: * IDENTIFICAR EL TIPO DE DEFECTO CON LETRA INICIAL RESALTADA | R44: * IDENTIFICAR EL TIPO DE DEFECTO CON LETRA INICIAL RESALTADA
...

Sheet SIMBOLOGIA
D3: SIGNIFICADO DE LA SIMBOLOGIA Symbol Meaning
A7: C: | B7: Ancho del aro exterior, Crapodina (Rod. Axial) es la altura
A8: D: | B8: Diámetro exterior del rodamiento / Bearing outside diameter
A9: VDp: | B9: Variación del diámetro exterior en un plano radial simple / Outside diameter variation in single radial plane
A10: reA: | B10: Dimensión axial del chaflán en el aro exterior / Outer ring axial chamfer dimension
A11: reR: | B11: Dimensión radial del chaflán en el aro exterior / Outer ring radial chamfer dimension
A12: B: | B12: Ancho del aro interior / Inner ring width Rodamiento Axial (Crapodina) Diametro interior mayor
A13: d: | B13: Diámetro del agujero del aro interior del rodamiento / Bearing bore diameter
A14: Vdp: | B14: Variación diametral del agujero del aro interior en un plano radial simple / Bore diameter variation in a single radial plane
A15: Vdmp: | B15: Conicidad del agujero del aro interior (diferencia de medida en ambos lados) / Mean bore diameter variation
A16: riA: | B16: Dimensión axial del chaflán en el aro interior / Inner ring axial chamfer dimension
A17: riR: | B17: Dimensión radial del claflán en el aro interior / Innedir ring radial chamfer dimension
A18: GR: | B18: Juego radial
... A20: Ra | B20: Rugosidad

Sheet Auxiliar
A1: Elegido | B1: 536 | C1: 3 | D1: 4 | E1: 5 | F1: 6 | G1: 7 | H1: 8 | I1: 9 | J1: 10 | K1: 11 | L1: 12 | M1: 13 | N1: 14 | O1: 15 | P1: 16 | Q1: 17 | R1: 18 | S1: 19 | T1: 20 | U1: 21 | V1: 22 | W1: 23 | X1: 24 | Y1: 25 | Z1: 26 | AA1: 27 | AB1: 28 | AC1: 29 | AD1: 30
A2: Numero | B2: Codigo | C2: C | D2: C+ | E2: C- | F2: D | G2: D+ | H2: D- | I2: B | J2: B+ | K2: B- | L2: d | M2: d+ | N2: d- | O2: GR | P2: GR+ | Q2: GR- | R2: GA | S2: GA+ | T2: GA- | U2: ARO INT+ | V2: ARO INT - | W2: ARO EXT + | X2: ARO EXT - | Y2: PORCENTAJE DE GRASA | Z2: TIPO DE GRASA | AA2: TORQUE DESELLOS + | AB2: TORQUE DESELLOS - | AC2: Fecha Rev. Plano | AD2: Rev.
A3: 1 | B3: 1207-TN-C3 | C3: 17 | D3: 0 | E3: -120 | F3: 72 | G3: 0 | H3: -13 | I3: 17 | J3: 0 | K3: -120 | L3: 35 | M3: 0 | N3: -12 | O3: C3 | P3: 40 | Q3: 23 | R3: NO | S3: NO | T3: NO | U3: 64 | V3: 58 | W3: 64 | X3: 58 | Y3: NO | Z3: NO | AA3: NO | AB3: NO | AC3: 42751 | AD3: 0
A4: 2 | B4: 1205 | C4: 15 | D4: 0 | E4: -120 | F4: 52 | G4: 0 | H4: -13 | I4: 15 | J4: 0 | K4: -120 | L4: 25 | M4: 0 | N4: -10 | AA4: ………….. | AB4: ………….. | AC4: …………… | AD4: ………
A5: 3 | B5: 1210 | C5: 20 | D5: 0 | E5: -120 | F5: 90 | G5: 0 | H5: -15 | I5: 20 | J5: 0 | K5: -120 | L5: 50 | M5: 0 | N5: -12 | O5: Axial (C0) | P5: 11 | Q5: 33 | AA5: ………….. | AB5: ………….. | AC5: …………… | AD5: ………
A6: 4 | B6: B&P-040-1211-K-C3-HLBR | C6: 21 | D6: 0 | E6: -150 | F6: 100 | G6: 0 | H6: -15 | I6: 21 | J6: 0 | K6: -150 | L6: 55 | M6: 46 | N6: 0 | O6: C3 | P6: 41 | Q6: 61 | R6: NO | S6: NO | T6: NO | U6: 58 HRC | V6: 65 HRC | W6: 58 HRC | X6: 65 HRC | Y6: NO | Z6: NO | AA6: NO | AB6: NO | AC6: 45397 | AD6: B
A7: 5 | B7: 1306 | C7: 19 | D7: 0 | E7: -120 | F7: 72 | G7: 0 | H7: -13 | I7: 19 | J7: 0 | K7: -120 | L7: 30 | M7: 0 | N7: -10 | O7: Axial (C0) | P7: 8 | Q7: 27 | AA7: ………….. | AB7: ………….. | AC7: …………… | AD7: ………
A8: 6 | B8: 1312 | C8: 31 | D8: 0 | E8: -150 | F8: 120 | G8: 0 | H8: -15 | I8: 31 | J8: 0 | K8: -150 | L8: 60 | M8: 0 | N8: -15 | O8: Axial (C0) | P8: 13 | Q8: 36 | AA8: ………….. | AB8: ………….. | AC8: …………… | AD8: ………
A9: 7 | B9: 2200 | C9: 14 | D9: 0 | E9: -120 | F9: 30 | G9: 0 | H9: -8 | I9: 14 | J9: 0 | K9: -120 | L9: 10 | M9: 0 | N9: -8 | AA9: ………….. | AB9: ………….. | AC9: …………… | AD9: ………
A10: 8 | B10: 2202 | C10: 14 | D10: 0 | E10: -120 | F10: 35 | G10: 0 | H10: -8 | I10: 14 | J10: 0 | K10: -120 | L10: 15 | M10: 0 | N10: -8 | AA10: ………….. | AB10: ………….. | AC10: …………… | AD10: ………
A11: 9 | B11: 2208 | C11: 23 | D11: 0 | E11: -120 | F11: 80 | G11: 0 | H11: -13 | I11: 23 | J11: 0 | K11: -120 | L11: 40 | M11: 0 | N11: -12 | R11: C0 | S11: 9 | T11: 29 | AA11: ………….. | AB11: ………….. | AC11: …………… | AD11: ………
A12: 10 | B12: 5207 | C12: 27 | D12: 0 | E12: -120 | F12: 72 | G12: 0 | H12: -13 | I12: 27 | J12: 0 | K12: -120 | L12: 35 | M12: 0 | N12: -12 | O12: Radial | P12: 25 | Q12: 12 | R12: NO | S12: NO | T12: NO | U12: 64 | V12: 58 | W12: 64 | X12: 58 | Y12: NO | Z12: NO | AA12: NO | AB12: NO | AC12: 42681 | AD12: 0
A13: 11 | B13: 6006 | C13: 13 | D13: 0 | E13: -120 | F13: 55 | G13: 0 | H13: -13 | I13: 13 | J13: 0 | K13: -120 | L13: 30 | M13: 0 | N13: -10 | O13: C0 | P13: 5 | Q13: 20 | AA13: ………….. | AB13: ………….. | AC13: …………… | AD13: ………
A14: 12 | B14: 6010 | C14: 16 | D14: 0 | E14: -120 | F14: 80 | G14: 0 | H14: -13 | I14: 16 | J14: 0 | K14: -120 | L14: 50 | M14: 0 | N14: -12 | O14: C0 | P14: 6 | Q14: 23 | AA14: ………….. | AB14: ………….. | AC14: …………… | AD14: ………
A15: 13 | B15: 6011 | C15: 18 | D15: 0 | E15: -150 | F15: 90 | G15: 0 | H15: -15 | I15: 18 | J15: 0 | K15: -150 | L15: 55 | M15: 0 | N15: -15 | O15: C0 | P15: 8 | Q15: 28 | AA15: ………….. | AB15: ………….. | AC15: …………… | AD15: ………
A16: 14 | B16: 6012 | C16: 18 | D16: 0 | E16: -150 | F16: 95 | G16: 0 | H16: -15 | I16: 18 | J16: 0 | K16: -150 | L16: 60 | M16: 0 | N16: -15 | O16: C3 | P16: 23 | Q16: 43 | AA16: ………….. | AB16: ………….. | AC16: …………… | AD16: ………
A17: 15 | B17: 6028 | C17: 33 | D17: 0 | E17: -120 | F17: 210 | G17: 0 | H17: -30 | I17: 33 | J17: 0 | K17: -120 | L17: 140 | M17: 0 | N17: -25 | O17: C3 | P17: 81 | Q17: 41 | R17: NO | S17: NO | T17: NO | U17: 64 | V17: 58 | W17: 64 | X17: 58 | Y17: ……………….. | Z17: Polyrex | AA17: ……………….. | AB17: ……………… | AC17: …………… | AD17: ………
A18: 16 | B18: 6207 | C18: 17 | D18: 0 | E18: -120 | F18: 72 | G18: 0 | H18: -13 | I18: 17 | J18: 0 | K18: -120 | L18: 35 | M18: 0 | N18: -12 | O18: C3 | P18: 15 | Q18: 33 | U18: 58 HRC | V18: 65 HRC | W18: 58 HRC | X18: 65 HRC | AA18: ………….. | AB18: ………….. | AC18: …………… | AD18: ………
A19: 17 | B19: 6209 | C19: 19 | D19: 0 | E19: -120 | F19: 85 | G19: 0 | H19: -15 | I19: 19 | J19: 0 | K19: -120 | L19: 45 | M19: 0 | N19: -12 | O19: C3 | P19: 18 | Q19: 36 | AA19: ………….. | AB19: ………….. | AC19: …………… | AD19: ………
A20: 18 | B20: 6211 | C20: 21 | D20: 0 | E20: -150 | F20: 100 | G20: 0 | H20: -15 | I20: 21 | J20: 0 | K20: -150 | L20: 55 | M20: 0 | N20: -15 | O20: C0 | P20: 8 | Q20: 28 | AA20: ………….. | AB20: ………….. | AC20: …………… | AD20: ………
A21: 19 | B21: 6308 | C21: 23 | D21: 0 | E21: -120 | F21: 90 | G21: 0 | H21: -15 | I21: 23 | J21: 0 | K21: -120 | L21: 40 | M21: 0 | N21: -12 | O21: C3 | P21: 15 | Q21: 33 | R21: NO | S21: NO | T21: NO | U21: 64 | V21: 58 | W21: 64 | X21: 58 | Y21: NO | Z21: NO | AA21: NO | AB21: NO | AC21: 42881 | AD21: 0
A22: 20 | B22: 16006 | C22: 9 | D22: 0 | E22: -120 | F22: 55 | G22: 0 | H22: -13 | I22: 9 | J22: 0 | K22: -120 | L22: 30 | M22: 0 | N22: -10 | AA22: ………….. | AB22: ………….. | AC22: …………… | AD22: ………
A23: 21 | B23: B&P-040-1205-TN-C3-HLBR | C23: 15 | D23: 0 | E23: -120 | F23: 52 | G23: 0 | H23: -13 | I23: 15 | J23: 0 | K23: -120 | L23: 25 | M23: 0 | N23: -10 | O23: C3 | P23: 19 | Q23: 35 | R23: NO | S23: NO | T23: NO | U23: 64 | V23: 58 | W23: 64 | X23: 58 | Y23: NO | Z23: NO | AA23: ………….. | AB23: ………….. | AC23: 45348 | AD23: B
A24: 22 | B24: B&P-040-1206-K-C3-HLBR | C24: 16 | D24: 0 | E24: -120 | F24: 62 | G24: 0 | H24: -13 | I24: 16 | J24: 0 | K24: -120 | L24: 30 | M24: 33 | N24: 0 | O24: C3 | P24: 39 | Q24: 23 | R24: NO | S24: NO | T24: NO | U24: 65 | V24: 60 | W24: 65 | X24: 60 | Y24: NO | Z24: NO | AA24: NO | AB24: NO | AC24: 45517 | AD24: A
A25: 23 | B25: B&P-040-1206-TN-C3-HLBR | C25: 16 | D25: 0 | E25: -120 | F25: 62 | G25: 0 | H25: -13 | I25: 16 | J25: 0 | K25: -120 | L25: 30 | M25: 0 | N25: -10 | O25: C3 | P25: 35 | Q25: 19 | R25: - | S25: - | T25: - | U25: 64 | V25: 58 | W25: 64 | X25: 58 | Y25: - | Z25: - | AA25: - | AB25: - | AC25: 14/08/2024 | AD25: B
A26: 24 | B26: 1208-K | C26: 18 | D26: 0 | E26: -120 | F26: 80 | G26: 0 | H26: -13 | I26: 18 | J26: 0 | K26: -120 | L26: 40 | M26: 0 | N26: -12 | O26: NO | P26: NO | Q26: NO | R26: NO | S26: NO | T26: NO | U26: NO | V26: NO | W26: NO | X26: NO | AA26: ………….. | AB26: ………….. | AC26: …………… | AD26: ………
A27: 25 | B27: 1208-TN-C3 | C27: 18 | D27: 0 | E27: -120 | F27: 80 | G27: 0 | H27: -13 | I27: 18 | J27: 0 | K27: -120 | L27: 40 | M27: 0 | N27: -12 | O27: C3 | P27: 40 | Q27: 23 | R27: NO | S27: NO | T27: NO | U27: 64 | V27: 58 | W27: 64 | X27: 58 | Y27: NO | Z27: NO | AA27: NO | AB27: NO | AC27: 42569 | AD27: 0
A28: 26 | B28: 1209-K | C28: 19 | D28: 0 | E28: -120 | F28: 85 | G28: 0 | H28: -15 | I28: 19 | J28: 0 | K28: -120 | L28: 45 | M28: 0 | N28: -12 | O28: C3 | P28: 18 | Q28: 36 | R28: NO | S28: NO | T28: NO | U28: NO | V28: NO | W28: NO | X28: NO | Y28: NO | Z28: NO | AA28: ………….. | AB28: ………….. | AC28: …………… | AD28: ………
A29: 27 | B29: 1209TN-C3 | C29: 19 | D29: 0 | E29: -120 | F29: 85 | G29: 0 | H29: -15 | I29: 19 | J29: 0 | K29: -120 | L29: 45 | M29: 0 | N29: -12 | O29: Radial (C3) | P29: 44 | Q29: 25 | R29: NO | S29: NO | T29: NO | U29: 64 | V29: 58 | W29: 64 | X29: 58 | Y29: NO | Z29: NO | AA29: NO | AB29: NO | AC29: 42569 | AD29: A
A30: 28 | B30: 1209-TN-C3 | C30: 19 | D30: 0 | E30: -120 | F30: 85 | G30: 0 | H30: -15 | I30: 19 | J30: 0 | K30: -120 | L30: 45 | M30: 0 | N30: -12 | O30: C3 | P30: 25 | Q30: 44 | R30: NO | S30: NO | T30: NO | U30: 64 | V30: 58 | W30: 64 | X30: 58 | Y30: NO | Z30: NO | AA30: NO | AB30: NO | AC30: 42569 | AD30: A
A31: 29 | B31: 1210K-C3 | C31: 20 | D31: 0 | E31: -120 | F31: 90 | G31: 0 | H31: -15 | I31: 20 | J31: 0 | K31: -120 | L31: 50 | M31: 39 | N31: 0 | O31: C3 | P31: 52 | Q31: 33 | R31: NO | S31: NO | T31: NO | U31: 64 | V31: 58 | W31: 64 | X31: 58 | Y31: NO | Z31: NO | AA31: ………….. | AB31: ………….. | AC31: …………… | AD31: ………
A32: 30 | B32: 1305-TN-C3 | C32: 17 | D32: 0 | E32: -120 | F32: 62 | G32: 0 | H32: -13 | I32: 17 | J32: 0 | K32: -120 | L32: 25 | M32: 0 | N32: -10 | O32: C3 | P32: 35 | Q32: 19 | R32: NO | S32: NO | T32: NO | U32: 64 | V32: 58 | W32: 64 | X32: 58 | Y32: NO | Z32: NO | AA32: NO | AB32: NO | AC32: 42569 | AD32: 0
A33: 31 | B33: B&P-040-1307-K-TN-C3-HLBR | C33: 21 | D33: 0 | E33: -120 | F33: 80 | G33: 0 | H33: -13 | I33: 21 | J33: 0 | K33: -120 | L33: 35 | M33: 25 | N33: 0 | O33: C3 | P33: 40 | Q33: 23 | R33: NO | S33: NO | T33: NO | U33: 65 | V33: 60 | W33: 65 | X33: 60 | Y33: NO | Z33: NO | AA33: NO | AB33: NO | AC33: 45141 | AD33: A
A34: 32 | B34: B&P-040-1309-TN-C3-HLBR | C34: 25 | D34: 0 | E34: -120 | F34: 100 | G34: 0 | H34: -15 | I34: 25 | J34: 0 | K34: -120 | L34: 45 | M34: 0 | N34: -12 | O34: Radial (C3) | P34: 25 | Q34: 44 | R34: NO | S34: NO | T34: NO | U34: 64 | V34: 58 | W34: 64 | X34: 58 | Y34: NO | Z34: NO | AA34: NO | AB34: NO | AC34: 45093 | AD34: A
A35: 33 | B35: 1310-TN-C3 | C35: 27 | D35: 0 | E35: -120 | F35: 110 | G35: 0 | H35: -15 | I35: 27 | J35: 0 | K35: -120 | L35: 50 | M35: 0 | N35: -12 | O35: C3 | P35: 25 | Q35: 44 | R35: NO | S35: NO | T35: NO | U35: 64 | V35: 58 | W35: 64 | X35: 58 | Y35: NO | Z35: NO | AA35: ………….. | AB35: ………….. | AC35: …………… | AD35: ………
A36: 34 | B36: 1604-ZZ | C36: 7.143 | D36: 0 | E36: -127 | F36: 22.225 | G36: 0 | H36: -12 | I36: 7.143 | J36: 0 | K36: -127 | L36: 9.525 | M36: 0 | N36: -12 | O36: C0 | P36: 2 | Q36: 13 | U36: 64HRc | V36: 58HRc | W36: 64HRc | X36: 58HRc | AA36: ………….. | AB36: ………….. | AC36: …………… | AD36: ………
A37: 35 | B37: 1607-ZZ | C37: 7.936 | D37: 0 | E37: -127 | F37: 23.018 | G37: 0 | H37: -12 | I37: 7.936 | J37: 0 | K37: -127 | L37: 11.113 | M37: 0 | N37: -20 | O37: C0 | P37: 3 | Q37: 18 | U37: 64HRc | V37: 58HRc | W37: 64HRc | X37: 58HRc | AA37: ………….. | AB37: ………….. | AC37: …………… | AD37: ………
A38: 36 | B38: 1621-RS (HLBR) | C38: 11.112 | D38: 0 | E38: -120 | F38: 34.925 | G38: 0 | H38: -11 | I38: 11.112 | J38: 0 | K38: -120 | L38: 12.7 | M38: 0 | N38: -8 | O38: C0 | P38: 18 | Q38: 3 | R38: NO | S38: NO | T38: NO | U38: 64 | V38: 58 | W38: 64 | X38: 58 | Y38: NO | Z38: Great Wall | AA38: standard | AB38: standard | AC38: 43088 | AD38: 0
A39: 37 | B39: 1635-2RLD | C39: 12.71 | D39: 0 | E39: -120 | F39: 44.45 | G39: 0 | H39: -11 | I39: 12.71 | J39: 0 | K39: -120 | L39: 19.05 | M39: 0 | N39: -10 | R39: C0 | S39: 5 | T39: 20 | U39: 58 HRC | V39: 64 HRC | W39: 58 HRC | X39: 64 HRC | Y39: 25%- 35% | Z39: chang chan#2 | AA39: ………….. | AB39: ………….. | AC39: …………… | AD39: ………
A40: 38 | B40: 2205-TN-C3 | C40: 18 | D40: 0 | E40: -120 | F40: 52 | G40: 0 | H40: -13 | I40: 18 | J40: 0 | K40: -120 | L40: 25 | M40: 0 | N40: -10 | O40: C3 | P40: 35 | Q40: 19 | R40: NO | S40: NO | T40: NO | U40: 64 | V40: 58 | W40: 64 | X40: 58 | Y40: NO | Z40: NO | AA40: NO | AB40: NO | AC40: 42569 | AD40: 0
...
