Workbook

Sheet R016-04
D1: REGISTRO DE INSPECCION DE PRODUCTO ROD. RODILLO AGUJA | T1: REGISTRO DE INSPECCION DE PRODUCTO ROD. RODILLO AGUJA
D3: NEEDLE ROLLER BEARING INSPECTION RECORD | T3: NEEDLE ROLLER BEARING INSPECTION RECORD
D5: R016 - 01 | H5: 42828 | J5: REV. | K5: 9 | L5: PAG. 01 - 01 | T5: R016 - 01 | X5: 42828 | Z5: REV. | AA5: 9 | AB5: PAG. 01 - 01
A7: UBIC. EN DEPOSITO / LOCATION IN DEPOSITS: | H7: PRODUCTO / PRODUCT: | Q7: UBIC. EN DEPOSITO / LOCATION IN DEPOSITS: | X7: PRODUCTO / PRODUCT:
A8: PROVEEDOR / SUPPLIER: | H8: =VLOOKUP(Auxiliar!B1,Auxiliar!A3:AH560,18,FALSE) -> 45657 | K8: REV. PRINT | N8: =VLOOKUP(Auxiliar!B1,Auxiliar!A3:AH560,19,FALSE) -> 0 | Q8: PROVEEDOR / SUPPLIER: | X8: =VLOOKUP(Auxiliar!B1,Auxiliar!A3:AH560,18,FALSE) -> 45657 | AA8: REV. PRINT | AD8: =VLOOKUP(Auxiliar!B1,Auxiliar!A3:AH560,19,FALSE) -> 0
A9: LUGAR DE INSPEC. / NAME OF INSPECTION FACILITY: | C9: LABORATORIO BPB | H9: CRITERIO DE MUESTRA / SAMPLE DISCRETION: | M9: Prod.Armado Partes | Q9: LUGAR DE INSPEC. / NAME OF INSPECTION FACILITY: | S9: LABORATORIO BPB | X9: CRITERIO DE MUESTRA / SAMPLE DISCRETION: | AC9: Prod.Armado Partes
A10: DOC. DE REF. (PO#/PI#): | H10: PARTIDA/ BATCH: | Q10: DOC. DE REF. (PO#/PI#): | X10: PARTIDA/ BATCH:
A11: ITEM | B11: D.NOMINAL / NOMINAL DIM. (mm) | C11: TOLERANCIA /TOLERANCE (µm) | D11: MEDICIONES /ACTUAL READINGS (µm) | N11: RESULTADO/ RESULT | Q11: ITEM | R11: D.NOMINAL / NOMINAL DIM. (mm) | S11: TOLERANCIA /TOLERANCE (µm) | T11: MEDICIONES /ACTUAL READINGS (µm) | AD11: RESULTADO/ RESULT
D13: Nº 1 | E13: Nº 2 | F13: Nº 3 | G13: Nº 4 | H13: Nº 5 | I13: Nº 6 | J13: Nº 7 | K13: Nº 8 | L13: Nº 9 | M13: Nº 10 | T13: Nº 1 | U13: Nº 2 | V13: Nº 3 | W13: Nº 4 | X13: Nº 5 | Y13: Nº 6 | Z13: Nº 7 | AA13: Nº 8 | AB13: Nº 9 | AC13: Nº 10
A14: d | B14: =VLOOKUP(Auxiliar!B1,Auxiliar!A3:AH500,3,FALSE) -> 20 | C14: =VLOOKUP(Auxiliar!B1,Auxiliar!A3:AH500,4,FALSE) -> 0 | Q14: d | R14: =VLOOKUP(Auxiliar!B1,Auxiliar!A3:AH500,3,FALSE) -> 20 | S14: =VLOOKUP(Auxiliar!B1,Auxiliar!A3:AH500,4,FALSE) -> 0
C15: =VLOOKUP(Auxiliar!B1,Auxiliar!A3:AH500,5,FALSE) -> -10 | S15: =VLOOKUP(Auxiliar!B1,Auxiliar!A3:AH500,5,FALSE) -> -10
A16: D | B16: =VLOOKUP(Auxiliar!B1,Auxiliar!A3:AH500,6,FALSE) -> 32 | C16: =VLOOKUP(Auxiliar!B1,Auxiliar!A3:AH500,7,FALSE) -> 0 | Q16: D | R16: =VLOOKUP(Auxiliar!B1,Auxiliar!A3:AH500,6,FALSE) -> 32 | S16: =VLOOKUP(Auxiliar!B1,Auxiliar!A3:AH500,7,FALSE) -> 0
C17: =VLOOKUP(Auxiliar!B1,Auxiliar!A3:AH500,8,FALSE) -> -11 | S17: =VLOOKUP(Auxiliar!B1,Auxiliar!A3:AH500,8,FALSE) -> -11
A18: C | B18: =VLOOKUP(Auxiliar!B1,Auxiliar!A3:AH500,9,FALSE) -> 20 | C18: =VLOOKUP(Auxiliar!B1,Auxiliar!A3:AH500,10,FALSE) -> 0 | Q18: C | R18: =VLOOKUP(Auxiliar!B1,Auxiliar!A3:AH500,9,FALSE) -> 20 | S18: =VLOOKUP(Auxiliar!B1,Auxiliar!A3:AH500,10,FALSE) -> 0
C19: =VLOOKUP(Auxiliar!B1,Auxiliar!A3:AH500,11,FALSE) -> -200 | S19: =VLOOKUP(Auxiliar!B1,Auxiliar!A3:AH500,11,FALSE) -> -200
A20: B | B20: =VLOOKUP(Auxiliar!B1,Auxiliar!A3:AH500,12,FALSE) -> NO | C20: =VLOOKUP(Auxiliar!B1,Auxiliar!A3:AH500,13,FALSE) -> NO | Q20: B | R20: =VLOOKUP(Auxiliar!B1,Auxiliar!A3:AH500,12,FALSE) -> NO | S20: =VLOOKUP(Auxiliar!B1,Auxiliar!A3:AH500,13,FALSE) -> NO
C21: =VLOOKUP(Auxiliar!B1,Auxiliar!A3:AH500,14,FALSE) -> NO | S21: =VLOOKUP(Auxiliar!B1,Auxiliar!A3:AH500,14,FALSE) -> NO
A22: Fw | B22: =VLOOKUP(Auxiliar!B1,Auxiliar!A3:AH500,15,FALSE) -> NO | C22: =VLOOKUP(Auxiliar!B1,Auxiliar!A3:AH500,17,FALSE) -> NO | Q22: Fw | R22: =VLOOKUP(Auxiliar!B1,Auxiliar!A3:AH500,15,FALSE) -> NO | S22: =VLOOKUP(Auxiliar!B1,Auxiliar!A3:AH500,17,FALSE) -> NO
C23: =VLOOKUP(Auxiliar!B1,Auxiliar!A3:AH500,17,FALSE) -> NO | S23: =VLOOKUP(Auxiliar!B1,Auxiliar!A3:AH500,17,FALSE) -> NO
A24: Cantidad de rodillos | Q24: Cantidad de rodillos
A25: GRABADO / MARKING | Q25: GRABADO / MARKING
A26: ASPECTO | B26: *Rayas, Golpes, Oxido, Desprendimiento de material | Q26: ASPECTO | R26: *Rayas, Golpes, Oxido, Desprendimiento de material
A27: * IDENTIFICAR EL TIPO DE DEFECTO CON LETRA INICIAL RESALTADA | Q27: * IDENTIFICAR EL TIPO DE DEFECTO CON LETRA INICIAL RESALTADA
C29: Total Lote | E29: Aprobado | H29: Retrabajar | K29: Scrap | M29: 2º Calidad | S29: Total Lote | U29: Aprobado | X29: Retrabajar | AA29: Scrap | AC29: 2º Calidad
A32: OBSERVACION: | Q32: OBSERVACION:
A39: FIRMA DEL INSPECTOR DE CALIDAD Y FECHA / NAME AND SIGNATURE OF THE INSPECTOR QUALITY | I39: PERMANENTE | Q39: FIRMA DEL INSPECTOR DE CALIDAD Y FECHA / NAME AND SIGNATURE OF THE INSPECTOR QUALITY | Y39: PERMANENTE

Sheet SIMBOLOGIA
D3: SIGNIFICADO DE LA SIMBOLOGIA Symbol Meaning
A7: C: | B7: Ancho exterior del rodamiento / width outside the bearing
A8: D: | B8: Diámetro exterior del rodamiento / Bearing outside diameter
A9: ReA: | B9: Dimensión axial del chaflán en el aro exterior / Outer ring axial chamfer dimension
A10: ReR: | B10: Dimensión radial del chaflán en el aro exterior / Outer ring radial chamfer dimension
A12: d: | B12: Diámetro del agujero del aro interior del rodamiento / Bearing bore diameter

Sheet Auxiliar
A1: Elegido | B1: 66 | C1: 3 | D1: 4 | E1: 5 | F1: 6 | G1: 7 | H1: 8 | I1: 9 | J1: 10 | K1: 11 | L1: 12 | M1: 13 | N1: 14 | O1: 15 | P1: 16 | Q1: 17 | R1: 18 | S1: 19
A2: Numero | B2: Codigo | C2: d | D2: d+ | E2: d- | F2: D | G2: D+ | H2: D- | I2: C | J2: C+ | K2: C- | L2: B | M2: B+ | N2: B- | O2: Fw | P2: Fw+ | Q2: Fw- | R2: Fecha Rev. Plano | S2: Rev. | T2: Observaciones
A3: 1 | B3: BA3616-ZOH | C3: 57.15 | D3: 53 | E3: 15 | F3: 66.675 | G3: NO | H3: NO | I3: 25.4 | J3: 0 | K3: -250 | L3: NO | M3: NO | N3: NO | O3: NO | P3: NO | Q3: NO | R3: ………………….. | S3: …..
A4: 2 | B4: B&P-035-BA-3616-ZOH - CWN | C4: 57.15 | D4: 53 | E4: 15 | F4: 66.675 | G4: NO | H4: NO | I4: 25.4 | J4: 0 | K4: -250 | L4: NO | M4: NO | N4: NO | O4: NO | P4: NO | Q4: NO | R4: 44369 | S4: F
A5: 3 | B5: BHA-1612-ZO | C5: 25.4 | D5: 38 | E5: 13 | F5: 33.338 | G5: NO | H5: NO | I5: 19.05 | J5: 0 | K5: -200 | L5: NO | M5: NO | N5: NO | O5: NO | P5: NO | Q5: NO | R5: ………………….. | S5: …..
A6: 4 | B6: B&P-035-BHA-1616-ZOH - CWN | C6: 25.4 | D6: 38 | E6: 13 | F6: 33.338 | G6: NO | H6: NO | I6: 25.4 | J6: 0 | K6: -200 | L6: NO | M6: NO | N6: NO | O6: NO | P6: NO | Q6: NO | R6: 44406 | S6: D
A7: 5 | B7: B&P-035-BHA-2020-ZO - CWN | C7: 31.75 | D7: 38 | E7: 13 | F7: 41.275 | G7: NO | H7: NO | I7: 31.75 | J7: 0 | K7: -250 | L7: NO | M7: NO | N7: NO | O7: NO | P7: NO | Q7: NO | R7: 44369 | S7: E
A8: 6 | B8: BPB-035-HK-2526-JSGY | C8: 25 | D8: 41 | E8: 20 | F8: 32 | G8: NO | H8: NO | I8: 26 | J8: 0 | K8: 250 | L8: NO | M8: NO | N8: NO | O8: NO | P8: NO | Q8: NO | R8: 45657 | S8: B
A9: 7 | B9: HK-3016 | C9: 30 | D9: 41 | E9: 20 | F9: 37 | G9: NO | H9: NO | I9: 16 | J9: 0 | K9: -200 | L9: NO | M9: NO | N9: NO | O9: NO | P9: NO | Q9: NO | R9: 42438 | S9: A
A10: 8 | B10: NA4906-2RS | C10: 30 | D10: 0 | E10: -10 | F10: 47 | G10: 0 | H10: -11 | I10: 17 | J10: 0 | K10: -120 | L10: NO | M10: NO | N10: NO | O10: NO | P10: NO | Q10: NO | R10: ………………….. | S10: …..
A11: 9 | B11: NAV-4009 | C11: 45 | D11: NO | E11: NO | F11: 75 | G11: NO | H11: NO | I11: 30 | J11: NO | K11: NO | L11: NO | M11: NO | N11: NO | O11: NO | P11: NO | Q11: NO | R11: ………………….. | S11: …..
A12: 10 | B12: NAV-4011 | C12: 55 | D12: 0 | E12: 15 | F12: 90 | G12: 0 | H12: -15 | I12: 35 | J12: 0 | K12: -15 | L12: NO | M12: NO | N12: NO | O12: NO | P12: NO | Q12: NO | R12: ………………….. | S12: …..
A13: 11 | B13: BPB-035-NK-2520 - CWN | C13: 25 | D13: 33 | E13: -20 | F13: 33 | G13: 0 | H13: -11 | I13: 20 | J13: 0 | K13: -120 | L13: NO | M13: NO | N13: NO | O13: NO | P13: NO | Q13: NO | R13: 43369 | S13: B
A14: 12 | B14: BPB-035-NK-2830 - CWN | C14: 28 | D14: 33 | E14: -20 | F14: 37 | G14: 0 | H14: -11 | I14: 30 | J14: 0 | K14: -120 | L14: NO | M14: NO | N14: NO | O14: NO | P14: NO | Q14: NO | R14: 41831 | S14: A
A15: 13 | B15: NK2920 | C15: 29 | D15: 33 | E15: -20 | F15: 38 | G15: 0 | H15: -11 | I15: 20 | J15: 0 | K15: -120 | L15: NO | M15: NO | N15: NO | O15: NO | P15: NO | Q15: NO | R15: ………………….. | S15: …..
A16: 14 | B16: NK-3220 | C16: 32 | D16: 41 | E16: 25 | F16: 42 | G16: 0 | H16: -11 | I16: 20 | J16: 0 | K16: -120 | L16: NO | M16: NO | N16: NO | O16: NO | P16: NO | Q16: NO | R16: 42576 | S16: 0
A17: 15 | B17: NK-3230 | C17: 32 | D17: 41 | E17: 25 | F17: 42 | G17: 0 | H17: -11 | I17: 30 | J17: 0 | K17: -120 | L17: NO | M17: NO | N17: NO | O17: NO | P17: NO | Q17: NO | R17: 42576 | S17: 0
A18: 16 | B18: NK-3820 | C18: 38 | D18: 41 | E18: 25 | F18: 48 | G18: 0 | H18: -11 | I18: 20 | J18: 0 | K18: -120 | L18: NO | M18: NO | N18: NO | O18: NO | P18: NO | Q18: NO | R18: ………………….. | S18: …..
A19: 17 | B19: BPB-035-NK-5025 - CWN | C19: 50 | D19: 41 | E19: -25 | F19: 62 | G19: 0 | H19: -13 | I19: 25 | J19: 0 | K19: -120 | L19: NO | M19: NO | N19: NO | O19: NO | P19: NO | Q19: NO | R19: 43360 | S19: A
A20: 18 | B20: NKI-2020 | C20: 20 | D20: 0 | E20: -10 | F20: 32 | G20: 0 | H20: -11 | I20: 20 | J20: 0 | K20: -120 | L20: NO | M20: NO | N20: NO | O20: NO | P20: NO | Q20: NO | R20: 43070 | S20: 0
A21: 19 | B21: NKI-2520 | C21: 25 | D21: 0 | E21: 10 | F21: 38 | G21: 0 | H21: -11 | I21: 20 | J21: 0 | K21: -120 | L21: NO | M21: NO | N21: NO | O21: NO | P21: NO | Q21: NO | R21: ………………….. | S21: …..
A22: 20 | B22: RNA 69/28 | C22: 32 | D22: NO | E22: NO | F22: 45 | G22: 0 | H22: -11 | I22: 30 | J22: 0 | K22: -120 | L22: NO | M22: NO | N22: NO | O22: NO | P22: NO | Q22: NO | R22: ………………….. | S22: …..
A23: 21 | B23: RNA-6904 | C23: 25 | D23: NO | E23: NO | F23: 37 | G23: 0 | H23: -11 | I23: 30 | J23: 0 | K23: -120 | L23: NO | M23: NO | N23: NO | O23: NO | P23: NO | Q23: NO | R23: ………………….. | S23: …..
A24: 22 | B24: RNA-6905 | C24: 30 | D24: NO | E24: NO | F24: 42 | G24: 0 | H24: -11 | I24: 30 | J24: 0 | K24: -120 | L24: NO | M24: NO | N24: NO | O24: NO | P24: NO | Q24: NO | R24: ………………….. | S24: …..
A25: 23 | B25: TA-3820 | D25: NO | E25: NO | F25: 48 | G25: NO | H25: NO | I25: 20 | J25: 0 | K25: -250 | L25: NO | M25: NO | N25: NO | O25: NO | P25: NO | Q25: NO | R25: ………………….. | S25: …..
A26: 24 | B26: BPB-035-YB-3216 - CWN | C26: 50.8 | D26: 48 | E26: 15 | F26: 60.325 | G26: NO | H26: NO | I26: 25.4 | J26: 0 | K26: -250 | L26: NO | M26: NO | N26: NO | O26: NO | P26: NO | Q26: NO | R26: 42319 | S26: D
A27: 25 | B27: YB-3216 | C27: 50.8 | D27: NO | E27: NO | F27: 60.325 | G27: NO | H27: NO | I27: 25.4 | J27: NO | K27: NO | L27: NO | M27: NO | N27: NO | O27: NO | P27: NO | Q27: NO | R27: ………………….. | S27: …..
A28: 26 | B28: NA4907 | C28: 35 | D28: 0 | E28: -12 | F28: 55 | G28: 0 | H28: -13 | I28: 20 | J28: 0 | K28: -120 | L28: NO | M28: NO | N28: NO | O28: 42 | P28: NO | Q28: NO | R28: 42828 | S28: 0
A29: 27 | B29: S1720 | C29: 17 | D29: NO | E29: NO | F29: 23 | G29: NO | H29: NO | I29: 20 | J29: 0 | K29: -120 | L29: NO | M29: NO | N29: NO | O29: 17 | P29: NO | Q29: NO | R29: 42828 | S29: 0
A30: 28 | B30: NA4905 | C30: 25 | D30: 0 | E30: -10 | F30: 42 | G30: 0 | H30: -11 | I30: 17 | J30: 0 | K30: -120 | L30: NO | M30: NO | N30: NO | O30: NO | P30: NO | Q30: NO | R30: 42676 | S30: 0
A31: 29 | B31: HK-3020 | C31: 30 | D31: 41 | E31: 20 | F31: 37 | G31: 0 | H31: 0 | I31: 20 | J31: 0 | K31: -20 | L31: NO | M31: NO | N31: NO | O31: NO | P31: NO | Q31: NO | R31: 42676 | S31: 0
A32: 30 | B32: HK-5520 | C32: 55 | D32: 60 | E32: 30 | F32: 63 | G32: 0 | H32: 0 | I32: 20 | J32: 0 | K32: -20 | L32: NO | M32: NO | N32: NO | O32: NO | P32: NO | Q32: NO | R32: 42676 | S32: 0
A33: 31 | B33: BPB-035-BA-1816-ZOH - CWN | C33: 28.575 | D33: 38 | E33: 13 | F33: 34.925 | G33: NO | H33: NO | I33: 25.4 | J33: 0 | K33: -250 | L33: NO | M33: NO | N33: NO | O33: NO | P33: NO | Q33: NO | R33: 42965 | S33: 0
A34: 32 | B34: BPB-035-HK-3038 - CWN | C34: 30 | D34: 41 | E34: 20 | F34: 37 | G34: NO | H34: NO | I34: 38 | J34: 0 | K34: -250 | L34: NO | M34: NO | N34: NO | O34: NO | P34: NO | Q34: NO | R34: 43279 | S34: 0
A35: 33 | B35: BPB-035-RNA-4910 - BPB | C35: 58 | D35: 49 | E35: 30 | F35: 72 | G35: 0 | H35: -13 | I35: 22 | J35: 0 | K35: -120 | L35: NO | M35: NO | N35: NO | O35: NO | P35: NO | Q35: NO | R35: 43441 | S35: A
A36: 34 | B36: BPB-035-NK-2830 - CWN | C36: 28 | D36: 33 | E36: 20 | F36: 37 | G36: 0 | H36: -11 | I36: 30 | J36: 0 | K36: -120 | L36: NO | M36: NO | N36: NO | O36: NO | P36: NO | Q36: NO | R36: 41831 | S36: A
A37: 35 | B37: BPB-035-NK-3230-JSGY | C37: 32 | D37: 41 | E37: 25 | F37: 42 | G37: 0 | H37: -11 | I37: 30 | J37: 0 | K37: -120 | L37: NO | M37: NO | N37: NO | O37: NO | P37: NO | Q37: NO | R37: 46022 | S37: B
A38: 36 | B38: BPB-035-HK-3016-CWN | C38: 30 | D38: 41 | E38: 20 | F38: 37 | G38: NO | H38: NO | I38: 16 | J38: 0 | K38: -200 | L38: NO | M38: NO | N38: NO | O38: NO | P38: NO | Q38: NO | R38: 42438 | S38: A
A39: 37 | B39: BPB-035-NK-2930-JSGY | C39: 29 | D39: 33 | E39: 20 | F39: 38 | G39: 0 | H39: -11 | I39: 30 | J39: 0 | K39: -120 | L39: NO | M39: NO | N39: NO | O39: NO | P39: NO | Q39: NO | R39: 44369 | S39: A
A40: 38 | B40: BPB-035-NK-4520-JSGY | C40: 45 | D40: 50 | E40: 25 | F40: 55 | G40: 0 | H40: -33 | I40: 20 | J40: 0 | K40: -250 | L40: NO | M40: NO | N40: NO | O40: NO | P40: NO | Q40: NO | R40: 44636 | S40: A
...
