Workbook

Sheet R016-01
D1: REGISTRO DE INSPECCION DE PRODUCTO CUERPO PRINCIPAL CLIC
D5: R016 - 01 | H5: 43038 | J5: REV. | K5: 1 | L5: PAG. 01 - 01
A7: UBIC. EN DEPOSITO / LOCATION IN DEPOSITS: | H7: PRODUCTO / PRODUCT:
A8: PROVEEDOR / SUPPLIER: | H8: =VLOOKUP(Auxiliar!B1,Auxiliar!A3:BG250,58,FALSE) -> 0 | K8: REV. PRINT | N8: =VLOOKUP(Auxiliar!B1,Auxiliar!A3:BG250,57,FALSE) -> 0
H9: CRITERIO DE MUESTRA / SAMPLE DISCRETION: | K9: Dimensional - 1 pieza por turno
A10: LUGAR DE INSPEC. / NAME OF INSPECTION FACILITY: | C10: LABORATORIO BPB | K10: Visual - 4 piezas por turno
A11: DOC. DE REF. (PO#/PI#): | H11: PARTIDA/ BATCH:
A12: ITEM | B12: D.NOMINAL / NOMINAL DIM. (mm) | C12: TOLERANCIA / TOLERANCE (µm) | D12: MEDICIONES /ACTUAL READINGS (µm) | N12: RESULTADO/ RESULT
D14: Nº 1 | E14: Nº 2 | F14: Nº 3 | G14: Nº 4 | H14: Nº 5 | I14: Nº 6 | J14: Nº 7 | K14: Nº 8 | L14: Nº 9 | M14: Nº 10
B15: =VLOOKUP(Auxiliar!B1,Auxiliar!A3:AX250,3,FALSE) -> 20 | C15: =VLOOKUP(Auxiliar!B1,Auxiliar!A3:AS250,4,FALSE) -> NO
C16: =VLOOKUP(Auxiliar!B1,Auxiliar!A3:AS250,5,FALSE) -> NO
B17: =VLOOKUP(Auxiliar!B1,Auxiliar!A3:AS250,6,FALSE) -> Ø10 | C17: =VLOOKUP(Auxiliar!B1,Auxiliar!A3:AS250,7,FALSE) -> NO
C18: =VLOOKUP(Auxiliar!B1,Auxiliar!A3:AS250,8,FALSE) -> NO
B19: =VLOOKUP(Auxiliar!B1,Auxiliar!A3:AS250,9,FALSE) -> Ø14,5 | C19: =VLOOKUP(Auxiliar!B1,Auxiliar!A3:AS250,10,FALSE) -> 0.1
C20: =VLOOKUP(Auxiliar!B1,Auxiliar!A3:AS250,11,FALSE) -> 0
B21: =VLOOKUP(Auxiliar!B1,Auxiliar!A3:AS250,12,FALSE) -> 247 | C21: =VLOOKUP(Auxiliar!B1,Auxiliar!A3:AS250,13,FALSE) -> 0.1
C22: =VLOOKUP(Auxiliar!B1,Auxiliar!A3:AS250,14,FALSE) -> 0
B23: =VLOOKUP(Auxiliar!B1,Auxiliar!A3:AX250,15,FALSE) -> Ø17.5 | C23: =VLOOKUP(Auxiliar!B1,Auxiliar!A3:AS250,16,FALSE) -> 0
C24: =VLOOKUP(Auxiliar!B1,Auxiliar!A3:AS250,17,FALSE) -> -0.1
B25: =VLOOKUP(Auxiliar!B1,Auxiliar!A3:AS250,18,FALSE) -> M4x0,70 | C25: =VLOOKUP(Auxiliar!B1,Auxiliar!A3:AS250,19,FALSE) -> NO
C26: =VLOOKUP(Auxiliar!B1,Auxiliar!A3:AS250,20,FALSE) -> NO
B27: =VLOOKUP(Auxiliar!B1,Auxiliar!A3:AS250,21,FALSE) -> -1 | C27: =VLOOKUP(Auxiliar!B1,Auxiliar!A3:AS262,22,FALSE) -> 0.1
C28: =VLOOKUP(Auxiliar!B1,Auxiliar!A3:AS262,23,FALSE) -> 0
B29: =VLOOKUP(Auxiliar!B1,Auxiliar!A3:AS262,24,FALSE) -> M6x1 | C29: =VLOOKUP(Auxiliar!B1,Auxiliar!A3:AS262,25,FALSE) -> NO
C30: =VLOOKUP(Auxiliar!B1,Auxiliar!A3:AS262,26,FALSE) -> NO
B31: =VLOOKUP(Auxiliar!B1,Auxiliar!A3:AS262,27,FALSE) -> -10 | C31: =VLOOKUP(Auxiliar!B1,Auxiliar!A3:AS262,28,FALSE) -> 0.2
C32: =VLOOKUP(Auxiliar!B1,Auxiliar!A3:AS262,29,FALSE) -> -0.2
B33: =VLOOKUP(Auxiliar!B1,Auxiliar!A3:AS262,30,FALSE) -> 10 | C33: =VLOOKUP(Auxiliar!B1,Auxiliar!A3:AS262,31,FALSE) -> 0.2
C34: =VLOOKUP(Auxiliar!B1,Auxiliar!A3:AS262,32,FALSE) -> -0.2
B35: =VLOOKUP(Auxiliar!B1,Auxiliar!A3:AS262,33,FALSE) -> Ø7 | C35: =VLOOKUP(Auxiliar!B1,Auxiliar!A3:AS262,34,FALSE) -> 0.25
C36: =VLOOKUP(Auxiliar!B1,Auxiliar!A3:AS262,35,FALSE) -> 0
B37: =VLOOKUP(Auxiliar!B1,Auxiliar!A3:AS262,36,FALSE) -> Ø45,9 | C37: =VLOOKUP(Auxiliar!B1,Auxiliar!A3:AS262,37,FALSE) -> 0.1
C38: =VLOOKUP(Auxiliar!B1,Auxiliar!A3:AS262,38,FALSE) -> 0
B39: =VLOOKUP(Auxiliar!B1,Auxiliar!A3:AS262,39,FALSE) -> …….. | C39: =VLOOKUP(Auxiliar!B1,Auxiliar!A3:AS262,40,FALSE) -> ……
C40: =VLOOKUP(Auxiliar!B1,Auxiliar!A3:AS262,41,FALSE) -> …….
B41: =VLOOKUP(Auxiliar!B1,Auxiliar!A3:AS262,42,FALSE) -> ……… | C41: =VLOOKUP(Auxiliar!B1,Auxiliar!A3:AS262,43,FALSE) -> ………..
C42: =VLOOKUP(Auxiliar!B1,Auxiliar!A3:AS262,44,FALSE) -> ……….
B43: =VLOOKUP(Auxiliar!B1,Auxiliar!A3:AS262,45,FALSE) -> ……….. | C43: =VLOOKUP(Auxiliar!B1,Auxiliar!A3:AX262,46,FALSE) -> ……….
C44: =VLOOKUP(Auxiliar!B1,Auxiliar!A3:AX262,47,FALSE) -> ……..
B45: =VLOOKUP(Auxiliar!B1,Auxiliar!A3:AX262,48,FALSE) -> ………. | C45: =VLOOKUP(Auxiliar!B1,Auxiliar!A3:AX262,49,FALSE) -> ………..
...

Sheet Auxiliar
A1: Elegido | B1: 7 | C1: 3 | D1: 4 | E1: 5 | F1: 6 | G1: 7 | H1: 8 | I1: 9 | J1: 10 | K1: 11 | L1: 12 | M1: 13 | N1: 14 | O1: 15 | P1: 16 | Q1: 17 | R1: 18 | S1: 19 | T1: 20 | U1: 21 | V1: 22 | W1: 23 | X1: 24 | Y1: 25 | Z1: 26 | AA1: 27 | AB1: 28 | AC1: 29 | AD1: 30 | AE1: 31 | AF1: 32 | AG1: 33 | AH1: 34 | AI1: 35 | AJ1: 36 | AK1: 37 | AL1: 38 | AM1: 39 | AN1: 40 | AO1: 41 | AP1: 42 | AQ1: 43 | AR1: 44 | AS1: 45 | AT1: 46 | AU1: 47 | AV1: 48 | AW1: 49 | AX1: 50 | AY1: 51 | AZ1: 52 | BA1: 53 | BB1: 54 | BC1: 55 | BD1: 56 | BE1: 57 | BF1: 58 | BG1: 59
A2: Numero | B2: Codigo | C2: A | D2: Sup | E2: Inf | F2: B | G2: Sup | H2: Inf | I2: C | J2: Sup | K2: Inf | L2: D | M2: Sup | N2: Inf | O2: E | P2: Sup | Q2: Inf | R2: F | S2: Sup | T2: Inf | U2: G | V2: Sup | W2: Inf | X2: H | Y2: Sup | Z2: Inf | AA2: I | AB2: Sup | AC2: Inf | AD2: J | AE2: Sup | AF2: Inf | AG2: K | AH2: Sup | AI2: Inf | AJ2: L | AK2: Sup | AL2: Inf | AM2: M | AN2: Sup | AO2: Inf | AP2: N | AQ2: Sup | AR2: Inf | AS2: O | AT2: Sup | AU2: Inf | AV2: P | AW2: Sup | AX2: Inf | AY2: Q | AZ2: Sup | BA2: Inf | BB2: R | BC2: Sup | BD2: Inf | BE2: Rev | BF2: Fecha | BG2: Observacion
A3: 1 | B3: 9010 | C3: 52 | D3: 0.1 | E3: -0.1 | F3: 39.5 | G3: 0.2 | H3: 0 | I3: Ø12,5 | J3: 0.2 | K3: 0 | L3: Ø15,1 | M3: 0.1 | N3: 0 | O3: Ø18 | P3: 0.25 | Q3: 0 | R3: Ø10 | S3: 0.25 | T3: 0 | U3: 10.5 | V3: 0.1 | W3: -0.1 | X3: 27.5 | Y3: 0.2 | Z3: 0 | AA3: 57 | AB3: 0.1 | AC3: -0.1 | AD3: 62 | AE3: 0.1 | AF3: 0 | AG3: 39 | AH3: 0.3 | AI3: 0 | AJ3: Ø40 | AK3: 0,006 | AL3: -0.01 | AM3: 14.5 | AN3: 0.1 | AO3: -0.1 | AP3: 59.1 | AQ3: 0.1 | AR3: 0 | AS3: R125 | AT3: 0.2 | AU3: 0 | AV3: Ø10 | AW3: 0.25 | AX3: 0 | BE3: E | BF3: 43038
A4: 2 | B4: 9013 | C4: 52 | D4: 0.1 | E4: -0.1 | F4: 39.5 | G4: 0.2 | H4: 0 | I4: Ø12,5 | J4: 0.2 | K4: 0 | L4: Ø15 | M4: 0.15 | N4: 0.1 | O4: Ø18 | P4: 0.25 | Q4: 0 | R4: Ø10 | S4: 0.25 | T4: 0 | U4: 10.5 | V4: 0.1 | W4: -0.1 | X4: 27.5 | Y4: 0.2 | Z4: 0 | AA4: 57 | AB4: 0.1 | AC4: -0.1 | AD4: 62 | AE4: 0.1 | AF4: 0 | AG4: 39 | AH4: 0.3 | AI4: 0 | AJ4: Ø40 | AK4: 0,006 | AL4: -0.01 | AM4: 14.5 | AN4: 0.1 | AO4: -0.1 | AP4: 59.1 | AQ4: 0.1 | AR4: 0 | AS4: R125 | AT4: 0.2 | AU4: 0 | AV4: Ø10 | AW4: 0.25 | AX4: 0 | BE4: A | BF4: 43719
A5: 3 | B5: 9011 | C5: 20 | D5: NO | E5: NO | F5: Ø10 | G5: NO | H5: NO | I5: Ø14,5 | J5: 0.1 | K5: 0 | L5: 247 | M5: 0.1 | N5: 0 | O5: Ø17.5 | P5: 0 | Q5: -0.1 | R5: M4x0,70 | S5: NO | T5: NO | U5: -1 | V5: 0.1 | W5: 0 | X5: M6x1 | Y5: NO | Z5: NO | AA5: -10 | AB5: 0.2 | AC5: -0.2 | AD5: 10 | AE5: 0.2 | AF5: -0.2 | AG5: Ø7 | AH5: 0.25 | AI5: 0 | AJ5: Ø45,9 | AK5: 0.1 | AL5: 0 | AM5: …….. | AN5: …… | AO5: ……. | AP5: ……… | AQ5: ……….. | AR5: ………. | AS5: ……….. | AT5: ………. | AU5: …….. | AV5: ………. | AW5: ……….. | AX5: ……….. | AY5: ……… | AZ5: …….. | BA5: ………. | BB5: ………. | BC5: ……….. | BD5: …….. | BE5: E | BF5: 43038
A6: 4 | B6: 9014 | C6: 20 | D6: NO | E6: NO | F6: Ø10 | G6: NO | H6: NO | I6: Ø14,5 | J6: 0.1 | K6: 0 | L6: 247 | M6: 0.1 | N6: 0 | O6: Ø17.5 | P6: 0 | Q6: -0.1 | R6: M4x0,70 | S6: NO | T6: NO | U6: -1 | V6: 0.1 | W6: 0 | X6: M6x1 | Y6: NO | Z6: NO | AA6: -10 | AB6: 0.2 | AC6: -0.2 | AD6: 10 | AE6: 0.2 | AF6: -0.2 | AG6: Ø7 | AH6: 0.25 | AI6: 0 | AJ6: Ø45,9 | AK6: 0.1 | AL6: 0 | AM6: 13.5 | AN6: 0.1 | AO6: 0 | AP6: 7 | AQ6: NO | AR6: NO | BE6: 0 | BF6: 43626
A7: 5 | B7: BPB-037-609010-SYHX | C7: 52 | D7: 0.1 | E7: -0.1 | F7: 39.5 | G7: 0.2 | H7: 0 | I7: Ø12,5 | J7: 0.2 | K7: 0 | L7: Ø15,1 | M7: 0.1 | N7: 0 | O7: Ø18 | P7: 0.25 | Q7: 0 | R7: Ø10 | S7: 0.25 | T7: 0 | U7: 10.5 | V7: 0.1 | W7: -0.1 | X7: 27.5 | Y7: 0.2 | Z7: 0 | AA7: 57 | AB7: 0.1 | AC7: -0.1 | AD7: 62 | AE7: 0.1 | AF7: 0 | AG7: 39 | AH7: 0.3 | AI7: 0 | AJ7: Ø40 | AK7: 0,006 | AL7: -0.01 | AM7: 14.5 | AN7: 0.1 | AO7: -0.1 | AP7: 59.1 | AQ7: 0.1 | AR7: 0 | AS7: R125 | AT7: 0.2 | AU7: 0 | AV7: Ø10 | AW7: 0.25 | AX7: 0 | BE7: F | BF7: 43215
A8: 6 | B8: BPB-037-609011-SYHX | C8: 20 | D8: NO | E8: NO | F8: Ø10 | G8: NO | H8: NO | I8: Ø14,5 | J8: 0.1 | K8: 0 | L8: 247 | M8: 0.1 | N8: 0 | O8: Ø17.5 | P8: 0 | Q8: -0.1 | R8: M4x0,70 | S8: NO | T8: NO | U8: -1 | V8: 0.1 | W8: 0 | X8: M6x1 | Y8: NO | Z8: NO | AA8: -10 | AB8: 0.2 | AC8: -0.2 | AD8: 10 | AE8: 0.2 | AF8: -0.2 | AG8: Ø7 | AH8: 0.25 | AI8: 0 | AJ8: Ø45,9 | AK8: 0.1 | AL8: 0 | AM8: …….. | AN8: …… | AO8: ……. | AP8: ……… | AQ8: ……….. | AR8: ………. | AS8: ……….. | AT8: ………. | AU8: …….. | AV8: ………. | AW8: ……….. | AX8: ……….. | AY8: ……… | AZ8: …….. | BA8: ………. | BB8: ………. | BC8: ……….. | BD8: …….. | BE8: F | BF8: 43523
A9: 7 | B9: 9011-MANI | C9: 20 | D9: NO | E9: NO | F9: Ø10 | G9: NO | H9: NO | I9: Ø14,5 | J9: 0.1 | K9: 0 | L9: 247 | M9: 0.1 | N9: 0 | O9: Ø17.5 | P9: 0 | Q9: -0.1 | R9: M4x0,70 | S9: NO | T9: NO | U9: -1 | V9: 0.1 | W9: 0 | X9: M6x1 | Y9: NO | Z9: NO | AA9: -10 | AB9: 0.2 | AC9: -0.2 | AD9: 10 | AE9: 0.2 | AF9: -0.2 | AG9: Ø7 | AH9: 0.25 | AI9: 0 | AJ9: Ø45,9 | AK9: 0.1 | AL9: 0 | AM9: …….. | AN9: …… | AO9: ……. | AP9: ……… | AQ9: ……….. | AR9: ………. | AS9: ……….. | AT9: ………. | AU9: …….. | AV9: ………. | AW9: ……….. | AX9: ……….. | AY9: ……… | AZ9: …….. | BA9: ………. | BB9: ………. | BC9: ……….. | BD9: ……..
A10: 8
A11: 9
